<?xml version="1.0"?>
<!--
Copied and modified from ROS1 example:
https://github.com/ros-simulation/gazebo_ros_demos/blob/kinetic-devel/rrbot_description/urdf/rrbot.gazebo
-->
<robot xmlns:xacro="http://ros.org/wiki/xacro">

  <xacro:macro name="wheel" params="prefix x y">
    <link name="${prefix}_wheel">
    <collision>
      <origin rpy="0 0 0" xyz="0 0 0"/>
      <geometry>
        <sphere radius="0.04"/>
      </geometry>
      <color rgba="0.2 0.2 0.2 1.0"/>
    </collision>
    <visual>
      <origin rpy="0 0 0" xyz="0 0 0"/>
      <geometry>
        <mesh filename="package://cross_description/meshes/wheel.stl" scale="0.0005 0.0005 0.0005"/>
      </geometry>
    </visual>
    <inertial>
      <origin rpy="0 0 0" xyz="0 0 0"/>
      <mass value="0.5"/>
      <inertia ixx="1.0" ixy="0.0" ixz="0.0" iyy="1.0" iyz="0.0" izz="1.0"/>
    </inertial>
    </link>

    <joint name="${prefix}_wheel_joint" type="continuous">
      <origin rpy="0 0 0" xyz="${x} ${y} 0"/>
      <parent link="base_link"/>
      <child link="${prefix}_wheel"/>
      <axis xyz="0 1 0"/>
    </joint>
  </xacro:macro>

</robot>
